Workbook

Sheet Cover & Control
A1: BANGLALINK IPO VALUATION MODEL
A2: Strictly Private & Confidential — Discussion Draft, Not for Distribution
B4: Prepared for: | C4: Banglalink Executive Committee / VEON Corporate Development / Investment Committee
B5: Prepared by: | C5: Telecom, Media & Technology — Investment Banking Division
B6: Companion document: | C6: Banglalink IPO Advisory Memorandum (v2, corrected against VEON Integrated Annual Report 2025)
B7: Model date: | C7: July 2026
A9: VERSION LOG
B10: Version | C10: Date | D10: Author | E10: Summary of Changes
B11: 1.0 | C11: July 2026 | D11: TMT IBD | E11: Initial build — full 19-tab architecture, calibrated to VEON FY2025 Integrated Annual Report disclosure
B12: 1.1 | C12: Jul 2026 | D12: TMT IBD | E12: Reviewed against Erik Aas 'Bangladesh: Growth Ambition 2027' presentation (Jul-2024, prior CEO). Added Management Guidance Tracker and IPO Readiness Scorecard tabs; cross-checked management's 2027 targets against FY2025A actuals and updated Base Case terminal EBITDA margin (46%->47%) accordingly. No other structural changes.
A14: NAVIGATION — CLICK TO JUMP TO TAB
B15: 01. Data Room Tracker
B16: 02. Management Guidance Tracker
B17: 03. Assumptions
B18: 04. Source Data
B19: 05. Comparable Companies
B20: 06. Operating Drivers
B21: 07. Subscriber & ARPU Fcst
B22: 08. Revenue Build
B23: 09. EBITDA Build
B24: 10. CapEx
B25: 11. Free Cash Flow
B26: 12. WACC
... B36: CONFIDENTIALITY: This workbook is a discussion draft. Every hardcoded input is color-coded blue; every cross-sheet link is green; every formula is black. Cells shaded orange/pending indicate information not yet available from the data room (see 'Data Room Tracker'). Do not overwrite pending cells with assumed values without updating the tracker.

Sheet Data Room Tracker
A1: DATA ROOM TRACKER
A2: Single source of truth for disclosed vs. assumed inputs — update BEFORE changing any formula elsewhere
B4: Category | C4: Status | D4: Source / Citation | E4: Last Updated | F4: Used In (Tab)
B5: Banglalink FY2024/FY2025 revenue, EBITDA, margin | C5: Disclosed | D5: VEON Integrated Annual Report 2025, p.97 | E5: Jul-2026 | F5: Source Data
B6: Banglalink digital revenue FY2024/FY2025 | C6: Disclosed | D6: VEON Integrated Annual Report 2025, p.98 | E6: Jul-2026 | F6: Source Data
B7: Banglalink 4G users & penetration FY2023-2025 | C7: Disclosed | D7: VEON Integrated Annual Report 2025, p.97-99 | E7: Jul-2026 | F7: Source Data / Operating Drivers
B8: Banglalink total customer base (VEON definition) | C8: Disclosed | D8: VEON Integrated Annual Report 2025, p.97 (34.4mn) | E8: Jul-2026 | F8: Source Data
B9: BTRC subscriber count (connections basis) | C9: Disclosed - reconcile | D9: BTRC, Sep-2025 (38.05mn) - NOT directly comparable to VEON customer count | E9: Jul-2026 | F9: Source Data
B10: Banglalink net debt / gross debt | C10: MISSING | D10: Not disclosed at segment level - VEON reports only consolidated group net debt | E10: - | F10: IPO Valuation Summary (blocking)
B11: Banglalink working capital detail | C11: MISSING | D11: Not disclosed at segment level | E11: - | F11: Free Cash Flow (set to zero, flagged)
B12: Banglalink capex — absolute BDT (2024 base) | C12: PARTIAL | D12: Only % change disclosed (-41.3% YoY FY2025); absolute FY2024 capex not found | E12: Jul-2026 | F12: CapEx
B13: Banglalink tax rate / cash taxes paid | C13: PARTIAL | D13: Qualitative only: 'reduction in minimum tax obligations' following licensing consolidation (23->6 categories) | E13: Jul-2026 | F13: Assumptions / Free Cash Flow
B14: IPO deal size, primary/secondary split, free float | C14: MISSING | D14: Not disclosed by Company or VEON | E14: - | F14: Assumptions / IPO Valuation Summary (blocking)
B15: Management 5-year business plan | C15: MISSING | D15: Not provided - DCF held inactive pending this input | E15: - | F15: DCF Valuation (held inactive)
... B23: IPO intent - prior CEO strategic slide vs. current CEO FY2025 report | C23: Disclosed - reconcile | D23: 2024 deck lists 'Future IPO' as a 2027 pillar; VEON FY2025 IAR (current CEO) does not mention a DSE listing. Open question, not a contradiction to resolve unilaterally. | E23: Jul-2026 | F23: IPO Readiness Scorecard
A24: STATUS SUMMARY (feeds Dashboard)
B25: Count — Disclosed | C25: =COUNTIF(C5:C20,"Disclosed") -> 8
B26: Count — Partial | C26: =COUNTIF(C5:C20,"PARTIAL") -> 2
B27: Count — Missing (blocking) | C27: =COUNTIF(C5:C20,"MISSING") -> 4
B28: Count — Disclosed, needs reconciliation | C28: =COUNTIF(C5:C20,"Disclosed - reconcile") -> 1

Sheet Management Guidance Tracker
A1: MANAGEMENT GUIDANCE TRACKER
A2: Source: "Bangladesh: Growth Ambition 2027" — Erik Aas (Banglalink CEO), presented Jul-2024. TREAT AS MANAGEMENT GUIDANCE, NOT OBJECTIVE TRUTH — unaudited, pre-turnaround, prior CEO (succeeded by Johan Buse, Apr-2025).
B4: CAUTION: This deck predates VEON's FY2025 Integrated Annual Report by ~18 months and was presented by a CEO who has since departed. Every target below is cross-checked against the latest disclosed actual, not assumed to still be management's live guidance.
B6: Target / Claim | C6: Management Guidance (Jul-2024) | D6: FY2025A Actual / Status | E6: RAG | F6: Recommended Treatment in Model
B7: Revenue growth (2023-2027 CAGR, LC) | C7: 15-18% CAGR (slide 7) | D7: FY24->FY25 revenue DECLINED -6.4% (BDT 59.7bn -> 55.9bn, VEON IAR 2025). Directionally opposite to guidance. | E7: RED | F7: DO NOT adopt as Base or Bull. Model's Base case (Assumptions row 13, connectivity ARPU -1%/yr + digital growth) is already more conservative and should stay so. Show management's ambition only as a memo line in Scenario Analysis for investor-facing contrast, explicitly labeled unmet.
B8: EBITDA margin ("improve to >45%") | C8: >45% by 2027 (slide 7) | D8: ALREADY EXCEEDED: FY2025A = 49.2% (VEON IAR 2025), vs. FY2024A 34.7%. | E8: GREEN | F8: Supports raising Assumptions Base Case terminal margin (row 18) modestly — recommend 46% -> 47%, since the disclosed actual already exceeds the 2027 target three years early. Do not raise Bear case; margin durability is still the model's single largest flagged risk.
B9: Digital revenue ("grow to 20% of total revenues") | C9: 20% of total revenue by 2027 (slide 7) | D9: 5.4% of total revenue in FY2025A (BDT 3.0bn of BDT 55.9bn), up from 0.6% in FY2024A. | E9: AMBER | F9: Do NOT adopt 20% into Base Case — would require ~4x the current growth trajectory to hit by 2027. Model as a BULL-CASE-ONLY reference point in Assumptions/Scenario Analysis, clearly labeled as management's aspiration, not the analyst base case.
B10: Equity Free Cash Flow >100mn USD annually ("to enable consistent dividends") | C10: USD 100mn+ EFCF/yr by 2027 (slide 7) | D10: Not directly comparable — VEON discloses EFCF at GROUP level only; Banglalink segment EFCF not disclosed. Model's Free Cash Flow tab computes UNLEVERED FCF (a different metric basis than VEON's EFCF definition — see Glossary). | E10: GREY | F10: Add a clearly-labeled memo reference in Free Cash Flow tab distinguishing Unlevered FCF (this model) from EFCF (VEON's guidance metric). Do not convert or force-fit management's EFCF target into the model's FCF bridge — the metrics are not equivalent without a levered adjustment.
B11: Toffee 2027 ambition: BDT 5bn service revenue | C11: BDT 5bn by 2027 (slide 5) | D11: Total Banglalink digital revenue (Toffee + MyBL + Ryze combined) was BDT 3.0bn in FY2025A — i.e., Toffee ALONE is targeted to exceed the entire current digital segment within ~2 years. | E11: RED | F11: Qualitative only. Do not build a Toffee-specific revenue line into Revenue Build — no disclosed Toffee-only actual exists to calibrate a forecast against, and the target appears aggressive relative to the current combined-segment base.
B12: MyBL 2027 ambition: 20mn MAU | C12: 20mn MAU by 2027 (slide 5) | D12: 8.1mn MAU in 4Q25 (VEON IAR 2025), +4.3% YoY — would require a step-change acceleration (~2.5x) to reach 20mn within ~2 years at current growth rates. | E12: AMBER | F12: Qualitative only (reference KPI). Not used in Revenue Build (digital revenue is forecast via growth rate, not MAU monetization — see Operating Drivers note). Track in this sheet each time new MAU data is disclosed.
B13: 4G rollout ("88% population coverage", 8x Ookla winner) | C13: 88% population coverage (2024); nationwide rollout complete (slide 3) | D13: VEON IAR 2025 discloses 4G PENETRATION OF SUBSCRIBER BASE (53.3%), a different metric than population coverage. Both can be true simultaneously (coverage vs. active usage) — not contradictory, but not directly comparable. | E13: GREEN | F13: Qualitative context only in Operating Drivers — population coverage (88%) is a network-reach metric, while the model's active driver (4G penetration of subscriber base) is the correct basis for revenue-relevant forecasting. Do not conflate the two metrics.
B14: Asset-light: tower sale (1/3 of towers, USD 100mn proceeds) | C14: Historical, completed by 2024 (slides 3-4) | D14: Historical/completed transaction, predates the FY2024A/FY2025A window modeled here. No incremental capex or cash impact in the forecast period. | E14: GREEN | F14: Reference only in CapEx tab. No formula impact — proceeds are historical and already embedded in whatever capex/balance-sheet base existed before this model's FY2025A starting point.
B15: Active network sharing | C15: "In discussions" as of 2024 (slide 3); listed as a 2027 capex-efficiency lever (slide 6) | D15: Not confirmed as completed or terminated in VEON's FY2025 Integrated Annual Report — status as of the latest disclosure is unknown. | E15: AMBER | F15: Add as a BULL-CASE-ONLY capex efficiency lever in CapEx tab (e.g., a further 1-2pp reduction in normalized network capex intensity), clearly flagged as contingent on an unconfirmed negotiation, not a Base Case assumption.
B16: Local funding: converting loans to local currency | C16: Stated 2027 strategic priority (slide 6) | D16: Not addressed in VEON's FY2025 Integrated Annual Report Bangladesh section reviewed for this workstream. | E16: GREY | F16: Qualitative only. Relevant context for the WACC tab's cost-of-debt/FX-risk discussion, but no quantified impact to model without further disclosure on loan terms or currency composition.
B17: Future IPO ("subject to market conditions") | C17: Explicitly listed under "Local funding" as a 2027 strategic priority (slide 6) — by prior CEO Erik Aas | D17: NOT restated in VEON's FY2025 Integrated Annual Report (current CEO Johan Buse, effective Apr-2025) — the FY2025 Bangladesh outlook/key priorities list does not mention a DSE listing (consistent with the flag already raised in the IPO Advisory Memorandum). | E17: AMBER | F17: IMPORTANT CORROBORATION, NOT CONTRADICTION: this confirms IPO intent existed under the prior CEO as recently as mid-2024, but its absence from the FY2025 report under new leadership is a genuine open question, not a fabrication of this workstream. Raise explicitly with VEON corporate development: has the IPO ambition been deprioritized, paused pending the turnaround, or simply not restated? See IPO Readiness Scorecard tab.
... B19: EV creation initiatives (spectrum leverage, non-telco DO1440 expansion, asset monetization, FX risk management) | C19: Listed as the four pillars of the 2027 strategy (slide 6) | D19: Directionally consistent with FY2025A results (digital revenue growth, capex discipline) but not independently quantifiable beyond what's already captured in EBITDA Build and CapEx. | E19: GREEN | F19: No new assumption required — these pillars are qualitative framing already consistent with the model's existing margin-bridge and capex-normalization logic.
A21: SUMMARY
B22: Overall read: management's MARGIN and DIGITAL-MIX-DIRECTION ambitions are tracking well or already exceeded; the headline REVENUE GROWTH ambition (15-18% CAGR) is currently being missed outright (FY25 revenue declined). This is an important, real tension for the equity story and should be presented to the Board as such — not smoothed over.

Sheet Assumptions
A1: ASSUMPTIONS
A2: Single input sheet — every other tab references this sheet only; no assumption should be hardcoded elsewhere
B4: ACTIVE SCENARIO: | C4: Base | E4: <- select Bear / Base / Bull. Drives the 'Active' column below and every downstream tab EXCEPT Scenario Analysis, which runs Bear/Base/Bull in parallel columns independent of this toggle (see that tab's notes).
B6: Category | C6: Assumption | D6: Bear | E6: Base | F6: Bull | G6: Active | H6: Source / Basis
A7: A. MACRO / FX
B8: USD/BDT average FX rate (BDT per USD) | C8: 126 | D8: 121.7 | E8: 118 | F8: =IF($C$4="Bear",C8,IF($C$4="Base",D8,E8)) -> 121.7 | G8: Base = VEON IAR 2025 p.143 FY2025 average rate (121.7); Bear/Bull are illustrative +/-4%
B9: Bangladesh CPI inflation (%/yr) | C9: 0.1 | D9: 0.087 | E9: 0.07 | F9: =IF($C$4="Bear",C9,IF($C$4="Base",D9,E9)) -> 0.087 | G9: Base = TradingEconomics, ~8.7% Mar-2026
B10: Bangladesh Bank policy rate (%) | C10: 0.11 | D10: 0.1 | E10: 0.09 | F10: =IF($C$4="Bear",C10,IF($C$4="Base",D10,E10)) -> 0.1 | G10: Base = TradingEconomics, ~10% policy rate
A11: B. OPERATING DRIVERS
B12: Total customer base growth (%/yr) | C12: -0.02 | D12: 0.01 | E12: 0.03 | F12: =IF($C$4="Bear",C12,IF($C$4="Base",D12,E12)) -> 0.01 | G12: Base year 34.4mn per VEON IAR 2025 p.97; market subscriber base shows saturation (Section 4.2 of memo)
B13: Connectivity ARPU growth (%/yr) | C13: -0.03 | D13: -0.01 | E13: 0.01 | F13: =IF($C$4="Bear",C13,IF($C$4="Base",D13,E13)) -> -0.01 | G13: Reflects flat-to-declining blended ARPU trend noted in memo Section 4.3
B14: Digital revenue growth (%/yr) | C14: 0.3 | D14: 0.55 | E14: 0.8 | F14: =IF($C$4="Bear",C14,IF($C$4="Base",D14,E14)) -> 0.55 | G14: Decelerating off FY2025's ~8x YoY growth (VEON IAR 2025 p.98) as base grows
B15: 4G penetration growth (pp/yr) | C15: 1 | D15: 2 | E15: 3 | F15: =IF($C$4="Bear",C15,IF($C$4="Base",D15,E15)) -> 2 | G15: Base year 53.3% (2024: 50.2%) per VEON IAR 2025 p.97
A16: C. MARGIN DRIVERS
B17: FY2025 EBITDA margin gain retained structurally (%) | C17: 0.7 | D17: 0.9 | E17: 1 | F17: =IF($C$4="Bear",C17,IF($C$4="Base",D17,E17)) -> 0.9 | G17: Judgment call: how much of the 34.7%->49.2% FY24->FY25 margin gain is structural (digital mix, network efficiency) vs. a one-year effect of the 41.3% capex cut. THIS IS THE SINGLE LARGEST SWING FACTOR IN THE MODEL.
B18: Terminal EBITDA margin (%) | C18: 0.4 | D18: 0.47 | E18: 0.5 | F18: =IF($C$4="Bear",C18,IF($C$4="Base",D18,E18)) -> 0.47 | G18: Base raised 46%->47% following cross-check against management's >45% 2027 target, already exceeded at 49.2% FY25A (see Management Guidance Tracker and Assumptions Section H). Bear/Bull unchanged.
A19: D. CAPEX
B20: Normalized network capex intensity (% of revenue) | C20: 0.2 | D20: 0.16 | E20: 0.13 | F20: =IF($C$4="Bear",C20,IF($C$4="Base",D20,E20)) -> 0.16 | G20: FY2025 capex fell 41.3% YoY (VEON IAR 2025 p.98) to an unsustainably low level; this is the assumed NORMALIZED run-rate the model reverts to, not the FY2025 actual (absolute FY2024 capex in BDT not disclosed - see Data Room Tracker)
B21: Digital / fintech infrastructure capex (% of revenue) | C21: 0.01 | D21: 0.02 | E21: 0.03 | F21: =IF($C$4="Bear",C21,IF($C$4="Base",D21,E21)) -> 0.02 | G21: Analyst assumption - supports PSP/Toffee/MyBL platform scale-up
B22: 5G / 700MHz contingent capex (USD mn/yr, from FY2028E) | C22: 40 | D22: 20 | E22: 10 | F22: =IF($C$4="Bear",C22,IF($C$4="Base",D22,E22)) -> 20 | G22: Contingent overlay only - reflects memo Section 4.7/9 treatment of 5G as multi-year optionality, not committed capex
A23: E. WACC INPUTS
B24: Risk-free rate (%) | C24: 0.055 | D24: 0.045 | E24: 0.04 | F24: =IF($C$4="Bear",C24,IF($C$4="Base",D24,E24)) -> 0.045 | G24: US Treasury proxy - Bangladesh sovereign curve not directly used; country risk captured separately below
B25: Equity risk premium (%) | C25: 0.06 | D25: 0.06 | E25: 0.06 | F25: =IF($C$4="Bear",C25,IF($C$4="Base",D25,E25)) -> 0.06 | G25: Standard long-run US ERP assumption - held constant across cases
B26: Country risk premium - Bangladesh (%) | C26: 0.04 | D26: 0.03 | E26: 0.02 | F26: =IF($C$4="Bear",C26,IF($C$4="Base",D26,E26)) -> 0.03 | G26: Reflects political transition and fiscal-policy volatility flagged in memo Sections 4.9 and 12
B27: Unlevered beta proxy (GP/Robi average) | C27: 0.85 | D27: 0.85 | E27: 0.85 | F27: =IF($C$4="Bear",C27,IF($C$4="Base",D27,E27)) -> 0.85 | G27: See Comparable Companies tab - held constant across cases
B28: Pre-tax cost of debt (%) | C28: 0.09 | D28: 0.08 | E28: 0.07 | F28: =IF($C$4="Bear",C28,IF($C$4="Base",D28,E28)) -> 0.08 | G28: Analyst assumption pending confirmation of Banglalink's actual funding terms
B29: Target Debt / Total Capital (%) | C29: 0.2 | D29: 0.2 | E29: 0.2 | F29: =IF($C$4="Bear",C29,IF($C$4="Base",D29,E29)) -> 0.2 | G29: Proxied from GP/Robi capital structure - held constant across cases
B30: Cash tax rate (%) | C30: 0.275 | D30: 0.25 | E30: 0.225 | F30: =IF($C$4="Bear",C30,IF($C$4="Base",D30,E30)) -> 0.25 | G30: Base reflects VEON IAR 2025 p.97 disclosure of 'reduction in minimum tax obligations' following licensing consolidation (23->6 categories)
A31: F. VALUATION DISCOUNT / PREMIUM
B32: Scale / liquidity discount vs. GP & Robi peer multiples (%) | C32: 0.35 | D32: 0.25 | E32: 0.15 | F32: =IF($C$4="Bear",C32,IF($C$4="Base",D32,E32)) -> 0.25 | G32: Reflects Banglalink's smaller scale and (pre-IPO) lack of trading liquidity relative to GP/Robi
B33: DCF terminal growth rate (%) | C33: 0.03 | D33: 0.04 | E33: 0.05 | F33: =IF($C$4="Bear",C33,IF($C$4="Base",D33,E33)) -> 0.04 | G33: Held below Bangladesh nominal GDP growth as a discipline check
A35: G. IPO STRUCTURE — PENDING MANAGEMENT / BSEC CONFIRMATION (NOT SCENARIO-DEPENDENT)
B36: Primary / secondary offering split (%) | C36: PENDING | G36: Not disclosed by Company/VEON - see memo Sections 9-10. Do NOT populate with an assumed figure.
B37: Target free float (%) | C37: PENDING | G37: Not disclosed by Company/VEON - see memo Sections 9-10. Do NOT populate with an assumed figure.
B38: Net debt at listing (USD mn) | C38: PENDING | G38: Not disclosed by Company/VEON - see memo Sections 9-10. Do NOT populate with an assumed figure.
B39: Post-money shares outstanding (mn) | C39: PENDING | G39: Not disclosed by Company/VEON - see memo Sections 9-10. Do NOT populate with an assumed figure.
A41: H. MANAGEMENT GUIDANCE REFERENCE (Erik Aas, Jul-2024 — REFERENCE ONLY, NOT AUTO-ADOPTED)
B42: Guidance Item | C42: Management Target | D42: Base Case Treatment | G42: Recommended Use | H42: Source
B43: Revenue CAGR 2023-2027 (LC) | C43: 15-18% | D43: NOT adopted — FY25 revenue declined -6.4% YoY, opposite direction | G43: Memo only / Scenario contrast | H43: Slide 7
B44: EBITDA margin target | C44: >45% by 2027 | D44: Already exceeded (49.2% FY25A) — Base terminal margin raised 46%->47% (see row 18) | G44: Adopted (modified Base) | H44: Slide 7
...

Sheet Source Data
A1: SOURCE DATA
A2: Verbatim historical data only — nothing on this tab is an assumption; every figure is cited
B4: Metric | C4: FY2024A | D4: FY2025A | E4: Unit | F4: Source
A5: BANGLALINK — SEGMENT FINANCIALS (VEON-DISCLOSED)
B6: Revenue | C6: 59.7 | D6: 55.9 | E6: BDT bn | F6: VEON Integrated Annual Report 2025, p.97
B7: EBITDA | C7: 20.7 | D7: 27.5 | E7: BDT bn | F7: VEON Integrated Annual Report 2025, p.97
B8: EBITDA margin (calculated) | C8: =C7/C6 -> 0.34673367 | D8: =D7/D6 -> 0.49194991 | E8: % | F8: Calculated — ties to VEON-disclosed 34.7% (2024) / 49.2% (2025)
B9: Digital revenue | C9: 0.34 | D9: 3 | E9: BDT bn | F9: VEON Integrated Annual Report 2025, p.98 (~8x YoY growth)
B10: Capex (YoY change only — see note) | D10: -0.413 | E10: % YoY | F10: VEON Integrated Annual Report 2025, p.98. ABSOLUTE FY2024/FY2025 capex in BDT NOT disclosed at segment level — see Data Room Tracker.
B11: 4G users (3-month active) | C11: 18 | D11: 18.4 | E11: mn | F11: VEON Integrated Annual Report 2025, p.97, 99
B12: 4G penetration | C12: 0.502 | D12: 0.533 | E12: % of base | F12: VEON Integrated Annual Report 2025, p.97, 99
B13: Total customers (VEON definition) | D13: 34.4 | E13: mn | F13: VEON Integrated Annual Report 2025, p.97
B14: MyBL monthly active users (4Q) | D14: 8.1 | E14: mn | F14: VEON Integrated Annual Report 2025, p.98 (+4.3% YoY)
B15: Toffee monthly active users (Dec) | D15: 6.4 | E15: mn | F15: VEON Integrated Annual Report 2025, p.98
B16: Ryze monthly active users | D16: 0.3 | E16: mn | F16: VEON Integrated Annual Report 2025, p.98 (+48.0% YoY)
B17: Multiplay adoption growth | D17: 0.236 | E17: % YoY | F17: VEON Integrated Annual Report 2025, p.98
A19: RECONCILIATION FLAG — CUSTOMER COUNT DISCREPANCY
B20: BTRC-sourced subscriber count (connections basis) | D20: 38.05 | E20: mn | F20: BTRC, Aug-2025. NOT directly comparable to VEON's 34.4mn 'customer' figure — likely reflects BTRC connections/SIMs basis vs. VEON's revenue-generating customer definition. DO NOT silently pick one — flag both to management for reconciliation.
A22: MARKET-WIDE DATA (BTRC / INDUSTRY PRESS, FY2024)
B23: Operator | C23: Revenue (BDT bn) | D23: Net Profit (BDT bn) | E23: Subscriber Share | F23: Source
B24: Grameenphone (DSE:GP) | C24: 158.45 | D24: 36.31 | E24: 0.457 | F24: BTRC / industry press, FY2024
B25: Robi Axiata (DSE:ROBI) | C25: 99.5 | D25: 7.03 | E25: 0.306 | F25: BTRC / industry press, FY2024
B26: Banglalink | C26: 59.7 | D26: n/d | E26: 0.202 | F26: VEON IAR 2025 (revenue); BTRC (share)
B27: Teletalk (state-owned) | C27: 5.52 | D27: n/d | E27: 0.035 | F27: BTRC / industry press, FY2024
A29: FX RATES (USD/BDT)
B30: Rate Type | C30: FY2024A | D30: FY2025A | E30: Unit | F30: Source
B31: Closing rate | C31: 119.6 | D31: 122.2 | E31: BDT/USD | F31: VEON Integrated Annual Report 2025, p.143
B32: Average rate | C32: 115.4 | D32: 121.7 | E32: BDT/USD | F32: VEON Integrated Annual Report 2025, p.143

Sheet Comparable Companies
A1: COMPARABLE COMPANIES
A2: Grameenphone (DSE:GP) and Robi Axiata (DSE:ROBI) — the only two direct, same-market, same-regulatory-regime peers
B4: Metric | C4: Grameenphone (GP) | D4: Robi Axiata (ROBI) | E4: Unit | F4: Source
B5: Market capitalization | C5: 375.9 | D5: 157.14 | E5: BDT bn | F5: stockanalysis.com (DSE:GP, DSE:ROBI), late-2025/early-2026 pricing
B6: Enterprise value | C6: n/d — not confirmed in sources reviewed | D6: 200.72 | E6: BDT bn | F6: Robi EV per stockanalysis.com; GP EV not confirmed in sources reviewed — flagged, not estimated
B7: LTM revenue | C7: 158.45 | D7: 99.5 | E7: BDT bn | F7: GP/Robi FY2024 disclosures (industry press)
B8: LTM EBITDA | C8: n/d | D8: n/d | E8: BDT bn | F8: Not confirmed in sources reviewed for either company — multiples below are as directly reported, not back-solved
B9: LTM net income | C9: 36.31 | D9: 7.03 | E9: BDT bn | F9: GP/Robi FY2024 disclosures (industry press)
B10: EV / EBITDA (LTM, as reported) | C10: 5.46 | D10: 4.19 | E10: x | F10: stockanalysis.com
B11: P/E (trailing) | C11: 11.67 | D11: 16.99 | E11: x | F11: stockanalysis.com
B12: P/E (forward) | C12: 10.06 | D12: 20 | E12: x | F12: stockanalysis.com
B13: Dividend yield | C13: 0.082 | D13: 0.05 | E13: % | F13: stockanalysis.com
A15: CALCULATED CROSS-CHECK MULTIPLES
B16: EV / Revenue (Robi — EV known) | C16: N/A — GP EV not confirmed | D16: =D6/D7 -> 2.0172864 | E16: x | F16: Calculated. GP EV/Revenue deliberately left blank rather than estimated from market cap alone (would understate EV by excluding net debt).
A18: BETA PROXY (FOR WACC)
B19: Unlevered beta (illustrative — see note) | C19: 0.85 | E19: x | F19: ASSUMPTION, NOT DISCLOSED: GP/Robi observed betas not sourced in this workstream. 0.85 is an illustrative emerging-market telecom proxy — replace with GP/Robi regression betas (e.g., 2-3yr weekly vs. DSE index) before this model is used for a live transaction.

Sheet Operating Drivers
A1: OPERATING DRIVERS
A2: Non-financial KPI engine — subscriber base, 4G penetration, digital adoption. Feeds Subscriber & ARPU Forecast.
B4: Metric | C4: FY2025A | D4: FY2026E | E4: FY2027E | F4: FY2028E | G4: FY2029E | H4: FY2030E | I4: Notes
A5: SUBSCRIBER BASE
B6: Total customers (mn) | C6: ='Source Data'!D13 -> 34.4 | D6: =C6*(1+Assumptions!$F$12) -> 34.744 | E6: =D6*(1+Assumptions!$F$12) -> 35.09144 | F6: =E6*(1+Assumptions!$F$12) -> 35.442354 | G6: =F6*(1+Assumptions!$F$12) -> 35.796778 | H6: =G6*(1+Assumptions!$F$12) -> 36.154746 | J6: Base FY2025A = VEON-reported 34.4mn. Grows at Assumptions active customer growth rate.
B7: 4G penetration (% of base) | C7: ='Source Data'!D12 -> 0.533 | D7: =MIN(C7+Assumptions!$F$15/100,0.95) -> 0.553 | E7: =MIN(D7+Assumptions!$F$15/100,0.95) -> 0.573 | F7: =MIN(E7+Assumptions!$F$15/100,0.95) -> 0.593 | G7: =MIN(F7+Assumptions!$F$15/100,0.95) -> 0.613 | H7: =MIN(G7+Assumptions!$F$15/100,0.95) -> 0.633 | J7: Base FY2025A = 53.3% (VEON-disclosed). Grows by active pp/yr assumption, capped at 95%.
B8: 4G users (mn, calculated) | C8: =C6*C7 -> 18.3352 | D8: =D6*D7 -> 19.213432 | E8: =E6*E7 -> 20.107395 | F8: =F6*F7 -> 21.017316 | G8: =G6*G7 -> 21.943425 | H8: =H6*H7 -> 22.885954 | J8: Calculated = Total customers x 4G penetration. FY2025A should tie to VEON-disclosed 18.4mn — see Audit Checks.
A10: DIGITAL PLATFORM REFERENCE KPIs (NOT USED IN REVENUE BUILD FORMULAS — CONTEXT ONLY)
B11: MyBL MAU (mn) | C11: ='Source Data'!D14 -> 8.1
B12: Toffee MAU (mn) | C12: ='Source Data'!D15 -> 6.4
B13: Ryze MAU (mn) | C13: ='Source Data'!D16 -> 0.3
B14: Digital revenue is forecast directly via a revenue growth rate (see Revenue Build), not a per-MAU monetization build, given no disclosed digital ARPU/monetization-per-user metric. These MAU figures are shown for context and future refinement only.

Sheet Subscriber & ARPU Fcst
A1: SUBSCRIBER & ARPU FORECAST
A2: Converts operating drivers into the two inputs Revenue Build needs: subscriber base and blended ARPU
B4: Metric | C4: FY2025A | D4: FY2026E | E4: FY2027E | F4: FY2028E | G4: FY2029E | H4: FY2030E | I4: Notes
A5: CUSTOMER BASE (LINKED)
B6: Total customers (mn) | C6: ='Operating Drivers'!C6 -> 34.4 | D6: ='Operating Drivers'!D6 -> 34.744 | E6: ='Operating Drivers'!E6 -> 35.09144 | F6: ='Operating Drivers'!F6 -> 35.442354 | G6: ='Operating Drivers'!G6 -> 35.796778 | H6: ='Operating Drivers'!H6 -> 36.154746
A8: CONNECTIVITY REVENUE & ARPU
B9: Connectivity revenue (BDT bn, FY2025A = Total - Digital) | C9: ='Source Data'!D6-'Source Data'!D9 -> 52.9
B10: Implied connectivity ARPU (BDT/month) | C10: =C9*1000000000/(C6*1000000)/12 -> 128.14922 | D10: =C10*(1+Assumptions!$F$13) -> 126.86773 | E10: =D10*(1+Assumptions!$F$13) -> 125.59906 | F10: =E10*(1+Assumptions!$F$13) -> 124.34306 | G10: =F10*(1+Assumptions!$F$13) -> 123.09963 | H10: =G10*(1+Assumptions!$F$13) -> 121.86864 | J10: FY2025A calculated (not disclosed directly). Forward = prior x (1+active connectivity ARPU growth).
B11: Forward connectivity revenue (BDT bn, calculated) | C11: =C6*C10*12/1000 -> 52.9 | D11: =D6*D10*12/1000 -> 52.89471 | E11: =E6*E10*12/1000 -> 52.889421 | F11: =F6*F10*12/1000 -> 52.884132 | G11: =G6*G10*12/1000 -> 52.878843 | H11: =H6*H10*12/1000 -> 52.873555 | J11: Formula: Customers(mn) x ARPU(BDT/mo) x 12 / 1000. FY2025A should tie to Connectivity revenue base row above — see Audit Checks.
A13: DIGITAL REVENUE (GROWTH-RATE BASIS — NOT PER-USER ARPU)
B14: Digital revenue (BDT bn) | C14: ='Source Data'!D9 -> 3 | D14: =C14*(1+Assumptions!$F$14) -> 4.65 | E14: =D14*(1+Assumptions!$F$14) -> 7.2075 | F14: =E14*(1+Assumptions!$F$14) -> 11.171625 | G14: =F14*(1+Assumptions!$F$14) -> 17.316019 | H14: =G14*(1+Assumptions!$F$14) -> 26.839829 | J14: FY2025A = VEON-disclosed BDT 3.0bn (~8x YoY). Forward growth decelerates per Assumptions active digital growth rate. Forecast directly via revenue growth rate, not a MyBL/Toffee MAU-based monetization build (no disclosed digital ARPU).

Sheet Revenue Build
A1: REVENUE BUILD
A2: Segment revenue tying subscriber/ARPU drivers to total revenue, reconciled to the FY2025A disclosed actual
B4: Metric | C4: FY2025A | D4: FY2026E | E4: FY2027E | F4: FY2028E | G4: FY2029E | H4: FY2030E | I4: Notes
A5: REVENUE BY SEGMENT (BDT bn)
B6: Connectivity revenue | C6: ='Subscriber & ARPU Fcst'!C11 -> 52.9 | D6: ='Subscriber & ARPU Fcst'!D11 -> 52.89471 | E6: ='Subscriber & ARPU Fcst'!E11 -> 52.889421 | F6: ='Subscriber & ARPU Fcst'!F11 -> 52.884132 | G6: ='Subscriber & ARPU Fcst'!G11 -> 52.878843 | H6: ='Subscriber & ARPU Fcst'!H11 -> 52.873555
B7: Digital revenue | C7: ='Subscriber & ARPU Fcst'!C14 -> 3 | D7: ='Subscriber & ARPU Fcst'!D14 -> 4.65 | E7: ='Subscriber & ARPU Fcst'!E14 -> 7.2075 | F7: ='Subscriber & ARPU Fcst'!F14 -> 11.171625 | G7: ='Subscriber & ARPU Fcst'!G14 -> 17.316019 | H7: ='Subscriber & ARPU Fcst'!H14 -> 26.839829
B8: Total revenue (BDT bn) | C8: =C6+C7 -> 55.9 | D8: =D6+D7 -> 57.54471 | E8: =E6+E7 -> 60.096921 | F8: =F6+F7 -> 64.055757 | G8: =G6+G7 -> 70.194862 | H8: =H6+H7 -> 79.713384
B9: Total revenue (USD mn, at active FX) | C9: =C8*1000/Assumptions!$F$8 -> 459.32621 | D9: =D8*1000/Assumptions!$F$8 -> 472.84067 | E9: =E8*1000/Assumptions!$F$8 -> 493.812 | F9: =F8*1000/Assumptions!$F$8 -> 526.34147 | G9: =G8*1000/Assumptions!$F$8 -> 576.78605 | H9: =H8*1000/Assumptions!$F$8 -> 654.99905 | J9: BDT bn x 1000 = BDT mn, divided by BDT/USD rate = USD mn
B10: YoY growth (%) | D10: =D8/C8-1 -> 0.029422361 | E10: =E8/D8-1 -> 0.044351784 | F10: =F8/E8-1 -> 0.065874192 | G10: =G8/F8-1 -> 0.095840025 | H10: =H8/G8-1 -> 0.13560141
A12: RECONCILIATION CHECK — MUST TIE TO ZERO IN FY2025A
B13: Total revenue (this build) vs. Source Data actual | C13: =C8-'Source Data'!D6 -> 0 | J13: Should equal exactly 0.0 by construction (connectivity = total - digital, both from Source Data). If non-zero, the build has a structural error — fix before extending forward. See Audit Checks.

Sheet EBITDA Build
A1: EBITDA BUILD
A2: Margin-bridge approach, not a single blended assumption — explains WHY margin moves, calibrated to the disclosed FY24->FY25 actual bridge
B4: Metric | C4: FY2025A | D4: FY2026E | E4: FY2027E | F4: FY2028E | G4: FY2029E | H4: FY2030E | I4: Notes
A5: HISTORICAL MARGIN BRIDGE (ACTUAL, FOR CALIBRATION)
B6: FY2024A EBITDA margin (actual) | C6: ='Source Data'!C8 -> 0.34673367
B7: FY2025A EBITDA margin (actual) | C7: ='Source Data'!D8 -> 0.49194991
A9: FORWARD MARGIN PATH — JUDGMENT-DRIVEN, NOT MECHANICAL
B10: 'New normal' margin (FY2026E starting point) | C10: =C6+(C7-C6)*Assumptions!$F$17 -> 0.47742829 | J10: Formula: FY24 margin + (FY25 margin - FY24 margin) x retention factor. Tests how much of the 34.7%->49.2% gain is structural vs. a one-year effect of the 41.3% capex cut, per Assumptions active retention factor.
B11: EBITDA margin (forecast path, linear to terminal by FY2030E) | C11: =C10 -> 0.47742829 | D11: =$C$10+(Assumptions!$F$18-$C$10)*1/5 -> 0.47594263 | E11: =$C$10+(Assumptions!$F$18-$C$10)*2/5 -> 0.47445697 | F11: =$C$10+(Assumptions!$F$18-$C$10)*3/5 -> 0.47297131 | G11: =$C$10+(Assumptions!$F$18-$C$10)*4/5 -> 0.47148566 | H11: =$C$10+(Assumptions!$F$18-$C$10)*5/5 -> 0.47 | J11: Linear interpolation from 'new normal' (FY2026E) to Assumptions active terminal margin (FY2030E).
A13: EBITDA CALCULATION
B14: Total revenue (BDT bn, linked) | C14: ='Revenue Build'!C8 -> 55.9 | D14: ='Revenue Build'!D8 -> 57.54471 | E14: ='Revenue Build'!E8 -> 60.096921 | F14: ='Revenue Build'!F8 -> 64.055757 | G14: ='Revenue Build'!G8 -> 70.194862 | H14: ='Revenue Build'!H8 -> 79.713384
B15: EBITDA (BDT bn) | C15: ='Source Data'!D7 -> 27.5 | D15: =D14*D11 -> 27.387981 | E15: =E14*E11 -> 28.513403 | F15: =F14*F11 -> 30.296535 | G15: =G14*G11 -> 33.095871 | H15: =H14*H11 -> 37.465291 | J15: FY2025A = Source Data actual (BDT 27.5bn). Forward = Revenue x forecast margin path.
B16: EBITDA (USD mn, at active FX) | C16: =C15*1000/Assumptions!$F$8 -> 225.96549 | D16: =D15*1000/Assumptions!$F$8 -> 225.04503 | E16: =E15*1000/Assumptions!$F$8 -> 234.29255 | F16: =F15*1000/Assumptions!$F$8 -> 248.94442 | G16: =G15*1000/Assumptions!$F$8 -> 271.94635 | H16: =H15*1000/Assumptions!$F$8 -> 307.84955
B17: EBITDA YoY growth (%) | D17: =D15/C15-1 -> -0.004073434 | E17: =E15/D15-1 -> 0.041091834 | F17: =F15/E15-1 -> 0.062536642 | G17: =G15/F15-1 -> 0.092397866 | H17: =H15/G15-1 -> 0.13202312

Sheet CapEx
A1: CAPEX
A2: Forward capex by category — FY2025 (-41.3% YoY) treated as an unsustainably low base, not the steady state
B4: Metric | C4: FY2025A | D4: FY2026E | E4: FY2027E | F4: FY2028E | G4: FY2029E | H4: FY2030E | I4: Notes
A5: HISTORICAL — FLAGGED DATA GAP
B6: Capex YoY change (disclosed) | C6: ='Source Data'!D10 -> -0.413 | J6: VEON discloses only the % change (-41.3% YoY FY2025), not absolute BDT figures at the segment level. Absolute FY2025A capex is therefore NOT populated here — see Data Room Tracker. Forward capex below is built bottom-up from revenue intensity, not grown off an unknown base.
A8: FORWARD CAPEX BUILD (BDT bn) — INTENSITY-BASED, NOT GROWN OFF FY2025A ACTUAL
B9: Total revenue (linked) | C9: ='Revenue Build'!C8 -> 55.9 | D9: ='Revenue Build'!D8 -> 57.54471 | E9: ='Revenue Build'!E8 -> 60.096921 | F9: ='Revenue Build'!F8 -> 64.055757 | G9: ='Revenue Build'!G8 -> 70.194862 | H9: ='Revenue Build'!H8 -> 79.713384
B10: Network capex (normalized intensity x revenue) | C10: n/a — FY2025A base not disclosed | D10: =D9*Assumptions!$F$20 -> 9.2071536 | E10: =E9*Assumptions!$F$20 -> 9.6155073 | F10: =F9*Assumptions!$F$20 -> 10.248921 | G10: =G9*Assumptions!$F$20 -> 11.231178 | H10: =H9*Assumptions!$F$20 -> 12.754141
B11: Digital / fintech infrastructure capex | C11: n/a | D11: =D9*Assumptions!$F$21 -> 1.1508942 | E11: =E9*Assumptions!$F$21 -> 1.2019384 | F11: =F9*Assumptions!$F$21 -> 1.2811151 | G11: =G9*Assumptions!$F$21 -> 1.4038972 | H11: =H9*Assumptions!$F$21 -> 1.5942677
B12: 5G / 700MHz contingent capex (USD mn active, from FY2028E) | C12: 0 | D12: 0 | E12: 0 | F12: =Assumptions!$F$22*Assumptions!$F$8/1000 -> 2.434 | G12: =Assumptions!$F$22*Assumptions!$F$8/1000 -> 2.434 | H12: =Assumptions!$F$22*Assumptions!$F$8/1000 -> 2.434 | J12: Zero through FY2027E — 5G/700MHz treated as multi-year optionality, not committed capex (memo Sections 4.7, 9). Converted from active USD mn assumption to BDT bn using active FX rate.
B13: Total capex (BDT bn) | C13: n/a | D13: =D10+D11+D12 -> 10.358048 | E13: =E10+E11+E12 -> 10.817446 | F13: =F10+F11+F12 -> 13.964036 | G13: =G10+G11+G12 -> 15.069075 | H13: =H10+H11+H12 -> 16.782409
B14: Capex intensity (% of revenue, calculated check) | C14: n/a | D14: =D13/D9 -> 0.18 | E14: =E13/E9 -> 0.18 | F14: =F13/F9 -> 0.21799815 | G14: =G13/G9 -> 0.2146749 | H14: =H13/H9 -> 0.2105344
A16: MANAGEMENT GUIDANCE CROSS-REFERENCE (Erik Aas presentation, Jul-2024)
B17: Tower monetization (historical, completed) | C17: 1/3 of towers sold, USD 100mn proceeds (slides 3-4) — historical/completed, predates this model's FY2025A base. No forward capex or cash-flow impact modeled.
B18: Active network sharing (unconfirmed — Bull-case lever only) | C18: Management cited this as 'in discussions' (2024) and a 2027 capex-efficiency pillar; status not confirmed in VEON's FY2025 disclosure. NOT built into Base Case network capex intensity (Assumptions row 20). If confirmed, would justify an additional 1-2pp reduction in normalized capex intensity beyond the current Bull case (13%). Update Assumptions directly if/when confirmed — do not hardcode here.

Sheet Free Cash Flow
A1: FREE CASH FLOW
A2: Unlevered FCF bridge — FY2025A left blank given the capex data gap; forecast years only
B4: Metric | C4: FY2025A | D4: FY2026E | E4: FY2027E | F4: FY2028E | G4: FY2029E | H4: FY2030E | I4: Notes
B5: EBITDA (BDT bn, linked) | C5: ='EBITDA Build'!C15 -> 27.5 | D5: ='EBITDA Build'!D15 -> 27.387981 | E5: ='EBITDA Build'!E15 -> 28.513403 | F5: ='EBITDA Build'!F15 -> 30.296535 | G5: ='EBITDA Build'!G15 -> 33.095871 | H5: ='EBITDA Build'!H15 -> 37.465291
B6: Less: Capex (BDT bn, linked) | C6: n/a — FY2025A absolute capex not disclosed | D6: =-CapEx!D13 -> -10.358048 | E6: =-CapEx!E13 -> -10.817446 | F6: =-CapEx!F13 -> -13.964036 | G6: =-CapEx!G13 -> -15.069075 | H6: =-CapEx!H13 -> -16.782409
B7: Less: Change in net working capital | C7: 0 | D7: 0 | E7: 0 | F7: 0 | G7: 0 | H7: 0 | J7: EXPLICIT SIMPLIFICATION, NOT AN OMISSION: Banglalink segment working-capital detail is not disclosed (see Data Room Tracker). Set to zero and flagged here rather than estimated as a % of revenue with no evidentiary basis.
B8: Less: Cash taxes (approx. — see note) | C8: n/a | D8: =-MAX(0,(D5+D6))*Assumptions!$F$30 -> -4.2574832 | E8: =-MAX(0,(E5+E6))*Assumptions!$F$30 -> -4.4239893 | F8: =-MAX(0,(F5+F6))*Assumptions!$F$30 -> -4.0831248 | G8: =-MAX(0,(G5+G6))*Assumptions!$F$30 -> -4.5066989 | H8: =-MAX(0,(H5+H6))*Assumptions!$F$30 -> -5.1707204 | J8: Taxable proxy = EBITDA - Capex (D&A approximated by Capex at steady state), x active cash tax rate. Simplification given no disclosed D&A schedule — refine once available.
B9: Unlevered Free Cash Flow (BDT bn) | C9: n/a | D9: =D5+D6+D7+D8 -> 12.77245 | E9: =E5+E6+E7+E8 -> 13.271968 | F9: =F5+F6+F7+F8 -> 12.249374 | G9: =G5+G6+G7+G8 -> 13.520097 | H9: =H5+H6+H7+H8 -> 15.512161
B10: Unlevered FCF (USD mn, at active FX) | C10: n/a | D10: =D9*1000/Assumptions!$F$8 -> 104.95028 | E10: =E9*1000/Assumptions!$F$8 -> 109.05479 | F10: =F9*1000/Assumptions!$F$8 -> 100.65221 | G10: =G9*1000/Assumptions!$F$8 -> 111.09365 | H10: =H9*1000/Assumptions!$F$8 -> 127.46229
A12: MANAGEMENT GUIDANCE CROSS-REFERENCE — METRIC BASIS CAUTION
B13: Management 2027 ambition: EFCF > USD 100mn/yr | C13: Erik Aas presentation, Jul-2024, slide 7 ("to enable consistent dividends") | F13: CAUTION: VEON defines EFCF (Equity Free Cash Flow) as free cash flow from operating + investing activities, excluding license payments/banking cash flows/M&A/deposit flows — a DIFFERENT metric than this tab's Unlevered FCF (EBITDA - Capex - NWC - Cash Taxes). Do not compare the two directly without an explicit bridge. Segment-level EFCF is not disclosed for Banglalink; only VEON group-level EFCF appears in VEON's reporting.

Sheet WACC
A1: WACC
A2: Discount rate build — CAPM cost of equity, blended with after-tax cost of debt
B4: Metric | C4: Value | D4: Notes
B5: Risk-free rate | C5: =Assumptions!F24 -> 0.045
B6: Equity risk premium | C6: =Assumptions!F25 -> 0.06
B7: Country risk premium (Bangladesh) | C7: =Assumptions!F26 -> 0.03 | D7: Isolated separately per Board request rather than folded into a generic ERP — reflects political transition and fiscal-policy volatility discussed in memo Sections 4.9, 12
B8: Beta (unlevered proxy, GP/Robi) | C8: =Assumptions!F27 -> 0.85
B9: Cost of equity (CAPM) | C9: =C5+C8*C6+C7 -> 0.126 | D9: Formula: Risk-free + Beta x ERP + Country risk premium
B11: Pre-tax cost of debt | C11: =Assumptions!F28 -> 0.08
B12: Cash tax rate | C12: =Assumptions!F30 -> 0.25
B13: After-tax cost of debt | C13: =C11*(1-C12) -> 0.06
B14: Target Debt / Total Capital | C14: =Assumptions!F29 -> 0.2
B16: WACC | C16: =C9*(1-C14)+C13*C14 -> 0.1128 | D16: Formula: Cost of equity x (1 - D/C) + After-tax cost of debt x D/C

Sheet DCF Valuation
A1: DCF VALUATION — INACTIVE PENDING BUSINESS PLAN
A2: Built for structural completeness. NOT for use in investment committee materials until management provides a validated business plan.
B4: STATUS: INACTIVE — outputs below are illustrative only, pending management business plan (see Data Room Tracker)
B6: Metric | C6: FY2026E | D6: FY2027E | E6: FY2028E | F6: FY2029E | G6: FY2030E | I6: Notes
B7: Unlevered FCF (USD mn, linked) | C7: ='Free Cash Flow'!D10 -> 104.95028 | D7: ='Free Cash Flow'!E10 -> 109.05479 | E7: ='Free Cash Flow'!F10 -> 100.65221 | F7: ='Free Cash Flow'!G10 -> 111.09365 | G7: ='Free Cash Flow'!H10 -> 127.46229
B8: Discount period (mid-year convention) | C8: 0.5 | D8: 1.5 | E8: 2.5 | F8: 3.5 | G8: 4.5
B9: WACC (linked) | C9: =WACC!C16 -> 0.1128
B10: Discount factor | C10: =1/(1+$C$9)^C8 -> 0.94796312 | D10: =1/(1+$C$9)^D8 -> 0.85187196 | E10: =1/(1+$C$9)^E8 -> 0.76552117 | F10: =1/(1+$C$9)^F8 -> 0.68792341 | G10: =1/(1+$C$9)^G8 -> 0.61819142
B11: PV of FCF (USD mn) | C11: =C7*C10 -> 99.488999 | D11: =D7*D10 -> 92.900718 | E11: =E7*E10 -> 77.051401 | F11: =F7*F10 -> 76.423919 | G11: =G7*G10 -> 78.796096
B13: Terminal growth rate (linked) | C13: =Assumptions!F33 -> 0.04
B14: Terminal value (undiscounted, USD mn) | C14: =G7*(1+C13)/(C9-C13) -> 1820.8899
B15: PV of terminal value (USD mn) | C15: =C14*G10 -> 1125.6585
B17: Implied Enterprise Value (USD mn) — INACTIVE | C17: =SUM(C11:G11)+C15 -> 1550.3196

Sheet Trading Multiples
A1: TRADING MULTIPLES
A2: Applies GP and Robi peer multiples to Banglalink's disclosed FY2025A EBITDA/Revenue — the primary near-term valuation method
B4: Metric | C4: GP-based | D4: Robi-based | E4: Unit | F4: Notes
B5: Banglalink FY2025A EBITDA (USD mn, linked) | C5: ='EBITDA Build'!C16 -> 225.96549
B6: Banglalink FY2025A revenue (USD mn, linked) | C6: ='Revenue Build'!C9 -> 459.32621
B8: Peer EV/EBITDA multiple (linked) | C8: ='Comparable Companies'!C10 -> 5.46 | D8: ='Comparable Companies'!D10 -> 4.19
B9: Scale/liquidity discount (active, linked) | C9: =Assumptions!F32 -> 0.25 | D9: =Assumptions!F32 -> 0.25
B10: Implied EV — EV/EBITDA method (USD mn) | C10: =$C$5*C8*(1-C9) -> 925.32868 | D10: =$C$5*D8*(1-D9) -> 710.09655
B12: Peer EV/Revenue multiple (Robi only — GP EV n/d, linked) | C12: N/A — GP EV not confirmed | D12: ='Comparable Companies'!D16 -> 2.0172864
B13: Implied EV — EV/Revenue cross-check (USD mn) | C13: N/A | D13: =$C$6*D12*(1-D9) -> 694.9444 | E13: Cross-check only

Sheet Scenario Analysis
A1: SCENARIO ANALYSIS (BEAR / BASE / BULL)
A2: Runs Bear/Base/Bull in parallel columns, independent of the Assumptions toggle — more robust than a toggle-and-record approach (see Cover notes)
B4: Metric | C4: Bear | D4: Base | E4: Bull | F4: Notes
B5: FY2025A Revenue (BDT bn, common base) | C5: ='Source Data'!D6 -> 55.9 | D5: ='Source Data'!D6 -> 55.9 | E5: ='Source Data'!D6 -> 55.9
B6: Revenue growth rate (%/yr, connectivity+digital blended proxy) | C6: =Assumptions!C12+(Assumptions!C14-Assumptions!C12)*0.1 -> 0.012 | D6: =Assumptions!D12+(Assumptions!D14-Assumptions!D12)*0.1 -> 0.064 | E6: =Assumptions!E12+(Assumptions!E14-Assumptions!E12)*0.1 -> 0.107 | F6: Condensed blended growth proxy = subscriber growth + 10% weight of the digital/connectivity growth gap, for a single-line revenue driver appropriate to a summary tab (full detail lives in Revenue Build).
B7: FY2030E Revenue (BDT bn, compounded 5yr) | C7: =C5*(1+C6)^5 -> 59.335468 | D7: =D5*(1+D6)^5 -> 76.228952 | E7: =E5*(1+E6)^5 -> 92.928711
B9: EBITDA margin retention factor (linked) | C9: =Assumptions!C17 -> 0.7 | D9: =Assumptions!D17 -> 0.9 | E9: =Assumptions!E17 -> 1
B10: Terminal EBITDA margin (linked) | C10: =Assumptions!C18 -> 0.4 | D10: =Assumptions!D18 -> 0.47 | E10: =Assumptions!E18 -> 0.5
B11: FY2030E EBITDA (BDT bn, at terminal margin) | C11: =C7*C10 -> 23.734187 | D11: =D7*D10 -> 35.827607 | E11: =E7*E10 -> 46.464355
B12: FY2030E EBITDA (USD mn) | C12: =C11*1000/Assumptions!$F$8 -> 195.02208 | D12: =D11*1000/Assumptions!$F$8 -> 294.39283 | E12: =E11*1000/Assumptions!$F$8 -> 381.79421
B14: Scale/liquidity discount (linked) | C14: =Assumptions!C32 -> 0.35 | D14: =Assumptions!D32 -> 0.25 | E14: =Assumptions!E32 -> 0.15
B15: Implied FY2030E EV — GP multiple applied (USD mn) | C15: =C12*'Comparable Companies'!$C$10*(1-C14) -> 692.13336 | D15: =D12*'Comparable Companies'!$C$10*(1-D14) -> 1205.5386 | E15: =E12*'Comparable Companies'!$C$10*(1-E14) -> 1771.9069
A17: MEMO: MANAGEMENT'S OWN 2027 AMBITION vs. MODEL SCENARIOS (reference only — different time horizon, not a 4th case)
B18: NOTE ON TIME HORIZON | C18: Management's targets are set for FY2027; this model's explicit forecast runs to FY2030E. Figures below are shown for directional context only, not a like-for-like comparison point.
B19: Metric | C19: Management 2027 Ambition | D19: Bear Case (this model) | E19: Base Case (this model)
B20: Revenue growth | C20: +15% to +18% CAGR (2023-2027) | D20: =Assumptions!C12 -> -0.02 | E20: =Assumptions!D12 -> 0.01
B21: EBITDA margin | C21: >45% by 2027 (already exceeded — 49.2% FY25A) | D21: =Assumptions!C18 -> 0.4 | E21: =Assumptions!D18 -> 0.47
B22: Digital revenue % of total | C22: 20% by 2027 | D22: Not modeled as a direct %; digital revenue grows off FY25A base at Bear-case growth rate (see Assumptions row 14)
B24: Full item-by-item cross-check of management's guidance against disclosed actuals: see 'Management Guidance Tracker' tab. Management's revenue-growth ambition is NOT reflected in either Bear or Base case — FY2025A results moved in the opposite direction (revenue declined). This is a deliberate modeling choice, not an oversight.

Sheet Sensitivity Analysis
A1: SENSITIVITY ANALYSIS
A2: Explicit-formula grids (not live Excel Data Tables, for portability/performance) — refresh manually if base-case assumptions change materially
A4: GRID 1 — IMPLIED EV (USD mn): FY2025A EBITDA x EXIT MULTIPLE
B5: Banglalink FY2025A EBITDA (USD mn, linked) | C5: ='EBITDA Build'!C16 -> 225.96549
B7: EV/EBITDA multiple -> | C7: 3 | D7: 3.5 | E7: 4 | F7: 4.5 | G7: 5
B8: Implied EV (USD mn) | C8: =$C$5*C$7 -> 677.89647 | D8: =$C$5*D$7 -> 790.87921 | E8: =$C$5*E$7 -> 903.86196 | F8: =$C$5*F$7 -> 1016.8447 | G8: =$C$5*G$7 -> 1129.8274
A11: GRID 2 — DCF: WACC x TERMINAL GROWTH (USD mn, illustrative — DCF inactive)
B12: WACC \ Term. Growth -> | C12: 0.02 | D12: 0.03 | E12: 0.04 | F12: 0.05 | G12: 0.06
B13: 0.09 | C13: =IFERROR('Free Cash Flow'!$H$9*1000/Assumptions!$F$8*(1+C$12)/(0.09-C$12),"n.m.") -> 1857.3077 | D13: =IFERROR('Free Cash Flow'!$H$9*1000/Assumptions!$F$8*(1+D$12)/(0.09-D$12),"n.m.") -> 2188.1027 | E13: =IFERROR('Free Cash Flow'!$H$9*1000/Assumptions!$F$8*(1+E$12)/(0.09-E$12),"n.m.") -> 2651.2157 | F13: =IFERROR('Free Cash Flow'!$H$9*1000/Assumptions!$F$8*(1+F$12)/(0.09-F$12),"n.m.") -> 3345.8852 | G13: =IFERROR('Free Cash Flow'!$H$9*1000/Assumptions!$F$8*(1+G$12)/(0.09-G$12),"n.m.") -> 4503.6677
B14: 0.1 | C14: =IFERROR('Free Cash Flow'!$H$9*1000/Assumptions!$F$8*(1+C$12)/(0.1-C$12),"n.m.") -> 1625.1442 | D14: =IFERROR('Free Cash Flow'!$H$9*1000/Assumptions!$F$8*(1+D$12)/(0.1-D$12),"n.m.") -> 1875.5166 | E14: =IFERROR('Free Cash Flow'!$H$9*1000/Assumptions!$F$8*(1+E$12)/(0.1-E$12),"n.m.") -> 2209.3464 | F14: =IFERROR('Free Cash Flow'!$H$9*1000/Assumptions!$F$8*(1+F$12)/(0.1-F$12),"n.m.") -> 2676.7082 | G14: =IFERROR('Free Cash Flow'!$H$9*1000/Assumptions!$F$8*(1+G$12)/(0.1-G$12),"n.m.") -> 3377.7508
B15: 0.11 | C15: =IFERROR('Free Cash Flow'!$H$9*1000/Assumptions!$F$8*(1+C$12)/(0.11-C$12),"n.m.") -> 1444.5727 | D15: =IFERROR('Free Cash Flow'!$H$9*1000/Assumptions!$F$8*(1+D$12)/(0.11-D$12),"n.m.") -> 1641.077 | E15: =IFERROR('Free Cash Flow'!$H$9*1000/Assumptions!$F$8*(1+E$12)/(0.11-E$12),"n.m.") -> 1893.7255 | F15: =IFERROR('Free Cash Flow'!$H$9*1000/Assumptions!$F$8*(1+F$12)/(0.11-F$12),"n.m.") -> 2230.5901 | G15: =IFERROR('Free Cash Flow'!$H$9*1000/Assumptions!$F$8*(1+G$12)/(0.11-G$12),"n.m.") -> 2702.2006
B16: 0.12 | C16: =IFERROR('Free Cash Flow'!$H$9*1000/Assumptions!$F$8*(1+C$12)/(0.12-C$12),"n.m.") -> 1300.1154 | D16: =IFERROR('Free Cash Flow'!$H$9*1000/Assumptions!$F$8*(1+D$12)/(0.12-D$12),"n.m.") -> 1458.7351 | E16: =IFERROR('Free Cash Flow'!$H$9*1000/Assumptions!$F$8*(1+E$12)/(0.12-E$12),"n.m.") -> 1657.0098 | F16: =IFERROR('Free Cash Flow'!$H$9*1000/Assumptions!$F$8*(1+F$12)/(0.12-F$12),"n.m.") -> 1911.9344 | G16: =IFERROR('Free Cash Flow'!$H$9*1000/Assumptions!$F$8*(1+G$12)/(0.12-G$12),"n.m.") -> 2251.8338
B17: 0.13 | C17: =IFERROR('Free Cash Flow'!$H$9*1000/Assumptions!$F$8*(1+C$12)/(0.13-C$12),"n.m.") -> 1181.9231 | D17: =IFERROR('Free Cash Flow'!$H$9*1000/Assumptions!$F$8*(1+D$12)/(0.13-D$12),"n.m.") -> 1312.8616 | E17: =IFERROR('Free Cash Flow'!$H$9*1000/Assumptions!$F$8*(1+E$12)/(0.13-E$12),"n.m.") -> 1472.8976 | F17: =IFERROR('Free Cash Flow'!$H$9*1000/Assumptions!$F$8*(1+F$12)/(0.13-F$12),"n.m.") -> 1672.9426 | G17: =IFERROR('Free Cash Flow'!$H$9*1000/Assumptions!$F$8*(1+G$12)/(0.13-G$12),"n.m.") -> 1930.1433
B19: Grid 2 uses FY2030E unlevered FCF as the terminal-value base cash flow (undiscounted grid, for illustration of sensitivity direction only — full PV-weighted DCF sits on the DCF Valuation tab and remains inactive pending business plan).

Sheet Football Field
A1: FOOTBALL FIELD VALUATION
A2: Consolidates every methodology into one range comparison — every figure traceable back to its source tab
B4: Methodology | C4: Low (USD mn) | D4: High (USD mn) | E4: Notes
B5: Trading Comps — EV/EBITDA (GP-based) | C5: ='Trading Multiples'!C10 -> 925.32868 | D5: ='Trading Multiples'!C10*1.15 -> 1064.128 | E5: High = +15% vs. Bull-case discount sensitivity, illustrative range around base-case point estimate
B6: Trading Comps — EV/EBITDA (Robi-based) | C6: ='Trading Multiples'!D10 -> 710.09655 | D6: ='Trading Multiples'!D10*1.15 -> 816.61103
B7: Trading Comps — EV/Revenue cross-check | C7: ='Trading Multiples'!D13*0.9 -> 625.44996 | D7: ='Trading Multiples'!D13*1.1 -> 764.43884
B8: Scenario-based (Bear-to-Bull, FY2030E EV) | C8: ='Scenario Analysis'!C15 -> 692.13336 | D8: ='Scenario Analysis'!E15 -> 1771.9069
B9: DCF (INACTIVE — pending business plan) | C9: ='DCF Valuation'!C17*0.85 -> 1317.7717 | D9: ='DCF Valuation'!C17*1.15 -> 1782.8676
B11: RECOMMENDED PRIMARY RANGE (Trading Comps only, excl. DCF) | C11: =MIN(C5,C6,C7) -> 625.44996 | D11: =MAX(D5,D6,D7) -> 1064.128

Sheet IPO Valuation Summary
A1: IPO VALUATION SUMMARY
A2: Bridges enterprise value to equity value and per-share terms — several outputs PENDING by design, not estimated
B4: Metric | C4: Low | D4: High | E4: Notes
B5: Enterprise Value (USD mn, Trading Comps range, linked) | C5: ='Football Field'!C11 -> 625.44996 | D5: ='Football Field'!D11 -> 1064.128
B6: Less: Net debt at listing (USD mn) | C6: PENDING | E6: Not disclosed by Company/VEON at segment level — see Data Room Tracker (BLOCKING item)
B7: Implied Equity Value (USD mn) | C7: PENDING — requires net debt above | E7: Formula = EV - Net Debt, held pending rather than computed off an assumed net debt figure
A9: OFFER STRUCTURE — ALL PENDING MANAGEMENT / BSEC CONFIRMATION
B10: Primary / secondary split | C10: PENDING | E10: Not disclosed — memo Sections 9-10. Do NOT populate with an assumed share count or price; a fabricated per-share figure would undermine the credibility of the entire valuation.
B11: Target free float (%) | C11: PENDING | E11: Not disclosed — memo Sections 9-10. Do NOT populate with an assumed share count or price; a fabricated per-share figure would undermine the credibility of the entire valuation.
B12: Post-money shares outstanding (mn) | C12: PENDING | E12: Not disclosed — memo Sections 9-10. Do NOT populate with an assumed share count or price; a fabricated per-share figure would undermine the credibility of the entire valuation.
B13: Implied offer price range (per share) | C13: PENDING | E13: Not disclosed — memo Sections 9-10. Do NOT populate with an assumed share count or price; a fabricated per-share figure would undermine the credibility of the entire valuation.

Sheet IPO Readiness Scorecard
A1: IPO READINESS SCORECARD
A2: Synthesizes the Advisory Memorandum, this workbook, and management's own strategic guidance into one readiness view for the Board
B4: Readiness Dimension | C4: Status | D4: Commentary | E4: Source
B5: Financial disclosure (top-line) | C5: READY | D5: Segment revenue, EBITDA, margin, digital revenue, and 4G KPIs are now disclosed via VEON's FY2025 Integrated Annual Report — a material improvement versus the standalone-opacity concern raised in early drafts of this workstream. | E5: VEON IAR 2025; Source Data tab
B6: Financial disclosure (sub-segment) | C6: NOT READY | D6: Net debt, working capital, tax detail, and absolute capex figures remain undisclosed at the Banglalink segment level — this is the single largest blocking item preventing a per-share valuation output (see IPO Valuation Summary tab). | E6: Data Room Tracker tab
B7: Operational turnaround durability | C7: PARTIAL | D7: FY2025 shows a strong, confirmed turnaround (EBITDA +32.5% YoY, margin to 49.2%), but this is one year of data. Management's own prior revenue-growth ambition (15-18% CAGR) was missed in the same period revenue actually declined. A second confirmed year is needed before treating the turnaround as structural rather than a strong single year. | E7: Management Guidance Tracker; Scenario Analysis
B8: Management strategic continuity | C8: OPEN QUESTION | D8: CEO transition (Erik Aas -> Johan Buse, Apr-2025) coincided with a change in stated priorities: the prior CEO's 2024 deck explicitly listed "Future IPO" as a 2027 strategic pillar; the new CEO's FY2025 disclosed priorities do not mention a DSE listing. This may reflect deprioritization, a pause pending the turnaround, or simply non-restatement — it should be raised directly with VEON corporate development before further workstream resourcing, not assumed either way. | E8: Management Guidance Tracker; Erik Aas presentation slide 6
B9: Regulatory relationship (BSEC) | C9: PARTIAL | D9: Constructive, multi-year public engagement history exists, but no confirmed pre-filing consultation on float sizing or pricing mechanism. | E9: IPO Advisory Memorandum Section 11
B10: Governance / board independence | C10: NOT READY | D10: No disclosed independent board component specific to a standalone Banglalink listing vehicle; governance currently operates through VEON's Group Authority Matrix and OpCo Board structure. | E10: IPO Advisory Memorandum Section 13.5
B11: Deal structure clarity | C11: NOT READY | D11: Primary/secondary split, target free float, and net debt are all undisclosed/PENDING. No per-share valuation can be produced until these are confirmed (IPO Valuation Summary tab deliberately left blank rather than estimated). | E11: IPO Valuation Summary tab
B12: Valuation framework readiness | C12: READY | D12: Full trading-comps and scenario valuation architecture is built and tie-checked (see Audit Checks tab); DCF is built but correctly held inactive pending a management business plan. | E12: Trading Multiples, Scenario Analysis, DCF Valuation, Audit Checks tabs
B13: Equity story differentiation | C13: PARTIAL | D13: PSP licence and digital-platform growth (Toffee/MyBL/Ryze) provide genuine differentiation vs. GP/Robi, but management's own 2027 targets for these platforms (Toffee BDT 5bn, MyBL 20mn MAU) are aggressive relative to current actuals and should not be presented to investors without caveats. | E13: Management Guidance Tracker
A15: OVERALL READINESS ASSESSMENT
B16: CONDITIONAL / NOT YET READY TO FILE. Consistent with the Advisory Memorandum's central recommendation: proceed to prepare (close the sub-segment disclosure gap, confirm deal structure, resolve the management strategic-continuity question), while deferring pricing until a second confirmed year of turnaround evidence is available.

Sheet Dashboard
A1: BANGLALINK IPO — BOARD DASHBOARD
A2: Prepared for Banglalink CEO/CFO and VEON Board — live-linked, refresh automatically on any assumption change
A4: FY2024 -> FY2025 TURNAROUND (VEON-DISCLOSED ACTUALS)
B5: Metric | C5: FY2024A | D5: FY2025A | E5: YoY | F5: Notes
B6: Revenue (BDT bn) | C6: ='Source Data'!C6 -> 59.7 | D6: ='Source Data'!D6 -> 55.9 | E6: =D6/C6-1 -> -0.063651591
B7: EBITDA (BDT bn) | C7: ='Source Data'!C7 -> 20.7 | D7: ='Source Data'!D7 -> 27.5 | E7: =D7/C7-1 -> 0.32850242
B8: EBITDA margin | C8: ='Source Data'!C8 -> 0.34673367 | D8: ='Source Data'!D8 -> 0.49194991 | E8: =D8/C8-1 -> 0.41881206
B9: Digital revenue (BDT bn) | C9: ='Source Data'!C9 -> 0.34 | D9: ='Source Data'!D9 -> 3 | E9: =D9/C9-1 -> 7.8235294
A11: VALUATION SUMMARY
B12: Implied Enterprise Value range (USD mn) | C12: ='Football Field'!C11 -> 625.44996 | D12: ='Football Field'!D11 -> 1064.128
A14: SCENARIO SUMMARY — FY2030E IMPLIED EV (USD mn)
C15: Bear | D15: Base | E15: Bull
B16: Implied EV | C16: ='Scenario Analysis'!C15 -> 692.13336 | D16: ='Scenario Analysis'!D15 -> 1205.5386 | E16: ='Scenario Analysis'!E15 -> 1771.9069
A18: TOP RISKS (FROM MEMORANDUM SECTION 12)
B19: 1. Fiscal policy volatility (VAT/duty on telecom sector) — Critical
B20: 2. Execution/timing — confirming FY2025 turnaround is structural, not a one-year effect — High
B21: 3. Sub-segment disclosure gap (net debt, working capital, tax detail) — High
A23: DATA ROOM READINESS STATUS
B24: Items Disclosed | C24: ='Data Room Tracker'!C22 -> 0
B25: Items Partial | C25: ='Data Room Tracker'!C23 -> Disclosed - reconcile
B26: Items Missing (blocking) | C26: ='Data Room Tracker'!C24 -> 0
A28: MANAGEMENT 2027 AMBITION vs. ACTUAL / MODEL FORECAST
B29: 2027 Ambition (management, Jul-2024) | C29: Target | D29: FY2025A Actual | E29: RAG
B30: Revenue growth | C30: 15-18% CAGR | D30: -6.4% YoY (FY24->FY25) | E30: RED
B31: EBITDA margin | C31: >45% | D31: 49.2% — already exceeded | E31: GREEN
B32: Digital revenue % of total | C32: 20% | D32: 5.4% | E32: AMBER
B33: EFCF | C33: >USD 100mn/yr | D33: n/d at segment level (different metric basis — see Free Cash Flow tab) | E33: GREY
B34: MyBL MAU | C34: 20mn | D34: 8.1mn | E34: AMBER
B35: Toffee revenue | C35: BDT 5bn | D35: n/d standalone (combined digital segment = BDT 3.0bn) | E35: GREY
B37: Detail: 'Management Guidance Tracker' tab. Readiness synthesis: 'IPO Readiness Scorecard' tab.

Sheet Audit Checks
A1: AUDIT CHECKS
A2: Run before every distribution of this model — this tab is the terminal diagnostic, not a presentation tab
B4: Check | C4: Result | D4: Pass? | E4: Notes
B5: Revenue Build FY2025A ties to Source Data actual | C5: ='Revenue Build'!C13 -> 0 | D5: =IF(ABS(C5)<0.01,"PASS","FAIL") -> PASS
B6: Operating Drivers 4G users FY2025A ties to VEON-disclosed 18.4mn (within rounding) | C6: ='Operating Drivers'!C8-'Source Data'!D11 -> -0.0648 | D6: =IF(ABS(C6)<0.15,"PASS (rounding)","FAIL") -> PASS (rounding) | E6: Small gap expected: 34.4mn customers x 53.3% penetration = 18.34mn vs. VEON's directly-disclosed 18.4mn — the two source metrics (total customer base vs. 3-month-active 4G users) are measured on slightly different bases in VEON's own disclosure.
B7: EBITDA Build FY2025A ties to Source Data actual (BDT 27.5bn) | C7: ='EBITDA Build'!C15-'Source Data'!D7 -> 0 | D7: =IF(ABS(C7)<0.01,"PASS","FAIL") -> PASS
B8: Assumptions Active column responds to scenario toggle (Base check) | C8: =Assumptions!F18-Assumptions!D18 -> 0 | D8: =IF(AND(Assumptions!$C$4="Base",ABS(C8)<0.0001),"PASS","CHECK SCENARIO TOGGLE") -> PASS
B9: WACC within plausible range (7%-16%) | C9: =WACC!C16 -> 0.1128 | D9: =IF(AND(C9>0.07,C9<0.16),"PASS","REVIEW") -> PASS
B10: Football Field low <= high | C10: ='Football Field'!D11-'Football Field'!C11 -> 438.67802 | D10: =IF(C10>=0,"PASS","FAIL") -> PASS
B11: Data Room Tracker — blocking items still flagged as PENDING (expected TRUE pre-data-room) | C11: ='IPO Valuation Summary'!C6 -> PENDING | D11: ="Expected: PENDING (net debt not yet disclosed)" -> Expected: PENDING (net debt not yet disclosed)
A13: OVERALL STATUS
B14: Model Status | C14: =IF(AND(D5="PASS",D6="PASS (rounding)",D7="PASS",D9="PASS",D10="PASS"),"ALL CHECKS PASS — model internally consistent","REVIEW REQUIRED — see failed checks above") -> ALL CHECKS PASS — model internally consistent
